Workbook

Sheet P&L
A1: M J P T & Co LLP
A2: Pristine Worldwide Private Limited
A4: P&L Analysis
A5: For the month of Mar 2026 | L5: Mar'26 | N5: (April to Mar) | X5: YTD'26
A6: Particulars | B6: Bluestreak | C6: Clarus | D6: IT | E6: Factory | F6: Office | G6: Common | H6: Spices - A to Z | I6: Spices - Vashi | J6: Total (without share trading) | K6: Share Trading | L6: Total (including share trading) | N6: Bluestreak | O6: Clarus | P6: IT | Q6: Factory | R6: Office | S6: Common | T6: Spices - A to Z | U6: Spices - Vashi | V6: Total (without share trading) | W6: Share Trading | X6: Total (including share trading)
A7: Sales | B7: =-SUMIFS('List of Ledgers '!$L:$L,'List of Ledgers '!$F:$F,'P&L'!$A$7,'List of Ledgers '!$G:$G,'P&L'!B6) -> 0 | C7: =-SUMIFS('List of Ledgers '!$L:$L,'List of Ledgers '!$F:$F,'P&L'!$A$7,'List of Ledgers '!$G:$G,'P&L'!C6) -> 28434.72 | D7: =-SUMIFS('List of Ledgers '!$L:$L,'List of Ledgers '!$F:$F,'P&L'!$A$7,'List of Ledgers '!$G:$G,'P&L'!D6) -> 0 | E7: =-SUMIFS('List of Ledgers '!$L:$L,'List of Ledgers '!$F:$F,'P&L'!$A$7,'List of Ledgers '!$G:$G,'P&L'!E6) -> 0 | F7: =-SUMIFS('List of Ledgers '!$L:$L,'List of Ledgers '!$F:$F,'P&L'!$A$7,'List of Ledgers '!$G:$G,'P&L'!F6) -> 0 | G7: =-SUMIFS('List of Ledgers '!$L:$L,'List of Ledgers '!$F:$F,'P&L'!$A$7,'List of Ledgers '!$G:$G,'P&L'!G6) -> 0 | H7: =-SUMIFS('List of Ledgers '!$L:$L,'List of Ledgers '!$F:$F,'P&L'!$A$7,'List of Ledgers '!$G:$G,'P&L'!H6) -> 0 | I7: =-SUMIFS('List of Ledgers '!$L:$L,'List of Ledgers '!$F:$F,'P&L'!$A$7,'List of Ledgers '!$G:$G,'P&L'!I6) -> 75012625 | J7: =SUM(B7:I7) -> 75041060 | K7: ='Shares(FIFO) '!J5 -> 0 | L7: =J7+K7 -> 75041060 | N7: =-SUMIFS('List of Ledgers '!$Q:$Q,'List of Ledgers '!$F:$F,'P&L'!$A$7,'List of Ledgers '!$G:$G,'P&L'!N6) -> 1770750.3 | O7: =-SUMIFS('List of Ledgers '!$Q:$Q,'List of Ledgers '!$F:$F,'P&L'!$A$7,'List of Ledgers '!$G:$G,'P&L'!O6) -> 837740.01 | P7: =-SUMIFS('List of Ledgers '!$Q:$Q,'List of Ledgers '!$F:$F,'P&L'!$A$7,'List of Ledgers '!$G:$G,'P&L'!P6) -> 1.0581533e+08 | Q7: =-SUMIFS('List of Ledgers '!$Q:$Q,'List of Ledgers '!$F:$F,'P&L'!$A$7,'List of Ledgers '!$G:$G,'P&L'!Q6) -> 0 | R7: =-SUMIFS('List of Ledgers '!$Q:$Q,'List of Ledgers '!$F:$F,'P&L'!$A$7,'List of Ledgers '!$G:$G,'P&L'!R6) -> 0 | S7: =-SUMIFS('List of Ledgers '!$Q:$Q,'List of Ledgers '!$F:$F,'P&L'!$A$7,'List of Ledgers '!$G:$G,'P&L'!S6) -> 0 | T7: =-SUMIFS('List of Ledgers '!$Q:$Q,'List of Ledgers '!$F:$F,'P&L'!$A$7,'List of Ledgers '!$G:$G,'P&L'!T6) -> 0 | U7: =-SUMIFS('List of Ledgers '!$Q:$Q,'List of Ledgers '!$F:$F,'P&L'!$A$7,'List of Ledgers '!$G:$G,'P&L'!U6)-1124270 -> 1.1989178e+08 | V7: =SUM(N7:U7) -> 2.283156e+08 | W7: ='Shares FIFO YTD'!J5 -> 0 | X7: =V7+W7 -> 2.283156e+08 | Y7: =V7-X7 -> 0
A8: Less: COGS | B8: =COGS!B11 -> 0 | C8: =COGS!C11 -> 28434.72 | D8: =COGS!D11 -> 16865.55 | E8: =COGS!E11 -> 0 | F8: =COGS!F11 -> 0 | G8: =COGS!G11 -> 16540 | I8: =COGS!H11 -> 69588312 | J8: =SUM(B8:I8) -> 69650152 | K8: =COGS!J11 -> 0 | L8: =J8+K8 -> 69650152 | N8: =COGS!B18 -> 1831803.4 | O8: =COGS!C18 -> 509355.46 | P8: =COGS!D18 -> 1.0231259e+08 | Q8: =COGS!E18 -> 0 | R8: =COGS!F18 -> 0 | S8: =COGS!G18 -> 17570 | U8: =COGS!H18 -> 1.1065439e+08 | V8: =SUM(N8:U8) -> 2.1532572e+08 | W8: =COGS!J18 -> 0 | X8: =V8+W8 -> 2.1532572e+08 | Y8: =V8-X8 -> 0
A9: 3. Direct Expense | B9: =SUM(B10:B14) -> 0 | C9: =SUM(C10:C14) -> 0 | D9: =SUM(D10:D14) -> 79554.92 | E9: =SUM(E10:E14) -> 0 | F9: =SUM(F10:F14) -> 0 | G9: =SUM(G10:G14) -> 18510 | H9: =SUM(H10:H14) -> 0 | I9: =SUM(I10:I14) -> 2088133.3 | J9: =SUM(B9:I9) -> 2186198.2 | K9: =SUM(K10:K14) -> 0 | L9: =J9+K9 -> 2186198.2 | N9: =SUM(N10:N14) -> 0 | O9: =SUM(O10:O14) -> 0 | P9: =SUM(P10:P14) -> 621733.82 | Q9: =SUM(Q10:Q14) -> 0 | R9: =SUM(R10:R14) -> 0 | S9: =SUM(S10:S14) -> 60190 | T9: =SUM(T10:T14) -> 0 | U9: =SUM(U10:U14) -> 3597029.3 | V9: =SUM(N9:U9) -> 4278953.1 | X9: =V9+W9 -> 4278953.1 | Y9: =V9-X9 -> 0
A10: Port Expenses | B10: =SUMIFS('List of Ledgers '!$L:$L,'List of Ledgers '!$F:$F,'P&L'!$A10,'List of Ledgers '!$G:$G,'P&L'!B$6) -> 0 | C10: =SUMIFS('List of Ledgers '!$L:$L,'List of Ledgers '!$F:$F,'P&L'!$A10,'List of Ledgers '!$G:$G,'P&L'!C$6) -> 0 | D10: =SUMIFS('List of Ledgers '!$L:$L,'List of Ledgers '!$F:$F,'P&L'!$A10,'List of Ledgers '!$G:$G,'P&L'!D$6) -> 0 | E10: =SUMIFS('List of Ledgers '!$L:$L,'List of Ledgers '!$F:$F,'P&L'!$A10,'List of Ledgers '!$G:$G,'P&L'!E$6) -> 0 | F10: =SUMIFS('List of Ledgers '!$L:$L,'List of Ledgers '!$F:$F,'P&L'!$A10,'List of Ledgers '!$G:$G,'P&L'!F$6) -> 0 | G10: =SUMIFS('List of Ledgers '!$L:$L,'List of Ledgers '!$F:$F,'P&L'!$A10,'List of Ledgers '!$G:$G,'P&L'!G$6) -> 0 | H10: =SUMIFS('List of Ledgers '!$L:$L,'List of Ledgers '!$F:$F,'P&L'!$A10,'List of Ledgers '!$G:$G,'P&L'!H$6) -> 0 | I10: =SUMIFS('List of Ledgers '!$L:$L,'List of Ledgers '!$F:$F,'P&L'!$A10,'List of Ledgers '!$G:$G,'P&L'!I$6) -> 1836553.2 | J10: =SUM(B10:I10) -> 1836553.2 | K10: =SUMIFS('List of Ledgers '!$L:$L,'List of Ledgers '!$F:$F,'P&L'!$A10,'List of Ledgers '!$G:$G,'P&L'!K$6) -> 0 | L10: =J10+K10 -> 1836553.2 | N10: =SUMIFS('List of Ledgers '!$Q:$Q,'List of Ledgers '!$F:$F,'P&L'!$A$10,'List of Ledgers '!$G:$G,'P&L'!N6) -> 0 | O10: =SUMIFS('List of Ledgers '!$Q:$Q,'List of Ledgers '!$F:$F,'P&L'!$A$10,'List of Ledgers '!$G:$G,'P&L'!O6) -> 0 | P10: =SUMIFS('List of Ledgers '!$Q:$Q,'List of Ledgers '!$F:$F,'P&L'!$A$10,'List of Ledgers '!$G:$G,'P&L'!P6) -> 242217.9 | Q10: =SUMIFS('List of Ledgers '!$Q:$Q,'List of Ledgers '!$F:$F,'P&L'!$A$10,'List of Ledgers '!$G:$G,'P&L'!Q6) -> 0 | R10: =SUMIFS('List of Ledgers '!$Q:$Q,'List of Ledgers '!$F:$F,'P&L'!$A$10,'List of Ledgers '!$G:$G,'P&L'!R6) -> 0 | S10: =SUMIFS('List of Ledgers '!$Q:$Q,'List of Ledgers '!$F:$F,'P&L'!$A$10,'List of Ledgers '!$G:$G,'P&L'!S6) -> 0 | T10: =SUMIFS('List of Ledgers '!$Q:$Q,'List of Ledgers '!$F:$F,'P&L'!$A$10,'List of Ledgers '!$G:$G,'P&L'!T6) -> 0 | U10: =SUMIFS('List of Ledgers '!$Q:$Q,'List of Ledgers '!$F:$F,'P&L'!$A$10,'List of Ledgers '!$G:$G,'P&L'!U6) -> 2785094.6 | V10: =SUM(N10:U10) -> 3027312.5 | X10: =V10+W10 -> 3027312.5 | Y10: =V10-X10 -> 0
A11: Loading & Unloading charges | B11: =SUMIFS('List of Ledgers '!$L:$L,'List of Ledgers '!$F:$F,'P&L'!$A11,'List of Ledgers '!$G:$G,'P&L'!B$6) -> 0 | C11: =SUMIFS('List of Ledgers '!$L:$L,'List of Ledgers '!$F:$F,'P&L'!$A11,'List of Ledgers '!$G:$G,'P&L'!C$6) -> 0 | D11: =SUMIFS('List of Ledgers '!$L:$L,'List of Ledgers '!$F:$F,'P&L'!$A11,'List of Ledgers '!$G:$G,'P&L'!D$6) -> 0 | E11: =SUMIFS('List of Ledgers '!$L:$L,'List of Ledgers '!$F:$F,'P&L'!$A11,'List of Ledgers '!$G:$G,'P&L'!E$6) -> 0 | F11: =SUMIFS('List of Ledgers '!$L:$L,'List of Ledgers '!$F:$F,'P&L'!$A11,'List of Ledgers '!$G:$G,'P&L'!F$6) -> 0 | G11: =SUMIFS('List of Ledgers '!$L:$L,'List of Ledgers '!$F:$F,'P&L'!$A11,'List of Ledgers '!$G:$G,'P&L'!G$6) -> 18510 | H11: =SUMIFS('List of Ledgers '!$L:$L,'List of Ledgers '!$F:$F,'P&L'!$A11,'List of Ledgers '!$G:$G,'P&L'!H$6) -> 0 | I11: =SUMIFS('List of Ledgers '!$L:$L,'List of Ledgers '!$F:$F,'P&L'!$A11,'List of Ledgers '!$G:$G,'P&L'!I$6) -> 0 | J11: =SUM(B11:I11) -> 18510 | K11: =SUMIFS('List of Ledgers '!$L:$L,'List of Ledgers '!$F:$F,'P&L'!$A11,'List of Ledgers '!$G:$G,'P&L'!K$6) -> 0 | L11: =J11+K11 -> 18510 | N11: =SUMIFS('List of Ledgers '!$Q:$Q,'List of Ledgers '!$F:$F,'P&L'!$A$11,'List of Ledgers '!$G:$G,'P&L'!N6) -> 0 | O11: =SUMIFS('List of Ledgers '!$Q:$Q,'List of Ledgers '!$F:$F,'P&L'!$A$11,'List of Ledgers '!$G:$G,'P&L'!O6) -> 0 | P11: =SUMIFS('List of Ledgers '!$Q:$Q,'List of Ledgers '!$F:$F,'P&L'!$A$11,'List of Ledgers '!$G:$G,'P&L'!P6) -> 4750 | Q11: =SUMIFS('List of Ledgers '!$Q:$Q,'List of Ledgers '!$F:$F,'P&L'!$A$11,'List of Ledgers '!$G:$G,'P&L'!Q6) -> 0 | R11: =SUMIFS('List of Ledgers '!$Q:$Q,'List of Ledgers '!$F:$F,'P&L'!$A$11,'List of Ledgers '!$G:$G,'P&L'!R6) -> 0 | S11: =SUMIFS('List of Ledgers '!$Q:$Q,'List of Ledgers '!$F:$F,'P&L'!$A$11,'List of Ledgers '!$G:$G,'P&L'!S6) -> 60190 | T11: =SUMIFS('List of Ledgers '!$Q:$Q,'List of Ledgers '!$F:$F,'P&L'!$A$11,'List of Ledgers '!$G:$G,'P&L'!T6) -> 0 | U11: =SUMIFS('List of Ledgers '!$Q:$Q,'List of Ledgers '!$F:$F,'P&L'!$A$11,'List of Ledgers '!$G:$G,'P&L'!U6) -> 0 | V11: =SUM(N11:U11) -> 64940 | X11: =V11+W11 -> 64940 | Y11: =V11-X11 -> 0
A12: Freight & Shipping charges | B12: =SUMIFS('List of Ledgers '!$L:$L,'List of Ledgers '!$F:$F,'P&L'!$A12,'List of Ledgers '!$G:$G,'P&L'!B$6) -> 0 | C12: =SUMIFS('List of Ledgers '!$L:$L,'List of Ledgers '!$F:$F,'P&L'!$A12,'List of Ledgers '!$G:$G,'P&L'!C$6) -> 0 | D12: =SUMIFS('List of Ledgers '!$L:$L,'List of Ledgers '!$F:$F,'P&L'!$A12,'List of Ledgers '!$G:$G,'P&L'!D$6) -> 81550.92 | E12: =SUMIFS('List of Ledgers '!$L:$L,'List of Ledgers '!$F:$F,'P&L'!$A12,'List of Ledgers '!$G:$G,'P&L'!E$6) -> 0 | F12: =SUMIFS('List of Ledgers '!$L:$L,'List of Ledgers '!$F:$F,'P&L'!$A12,'List of Ledgers '!$G:$G,'P&L'!F$6) -> 0 | G12: =SUMIFS('List of Ledgers '!$L:$L,'List of Ledgers '!$F:$F,'P&L'!$A12,'List of Ledgers '!$G:$G,'P&L'!G$6) -> 0 | H12: =SUMIFS('List of Ledgers '!$L:$L,'List of Ledgers '!$F:$F,'P&L'!$A12,'List of Ledgers '!$G:$G,'P&L'!H$6) -> 0 | I12: =SUMIFS('List of Ledgers '!$L:$L,'List of Ledgers '!$F:$F,'P&L'!$A12,'List of Ledgers '!$G:$G,'P&L'!I$6) -> 251580.08 | J12: =SUM(B12:I12) -> 333131 | K12: =SUMIFS('List of Ledgers '!$L:$L,'List of Ledgers '!$F:$F,'P&L'!$A12,'List of Ledgers '!$G:$G,'P&L'!K$6) -> 0 | L12: =J12+K12 -> 333131 | N12: =SUMIFS('List of Ledgers '!$Q:$Q,'List of Ledgers '!$F:$F,'P&L'!$A$12,'List of Ledgers '!$G:$G,'P&L'!N6) -> 0 | O12: =SUMIFS('List of Ledgers '!$Q:$Q,'List of Ledgers '!$F:$F,'P&L'!$A$12,'List of Ledgers '!$G:$G,'P&L'!O6) -> 0 | P12: =SUMIFS('List of Ledgers '!$Q:$Q,'List of Ledgers '!$F:$F,'P&L'!$A$12,'List of Ledgers '!$G:$G,'P&L'!P6) -> 196185.92 | Q12: =SUMIFS('List of Ledgers '!$Q:$Q,'List of Ledgers '!$F:$F,'P&L'!$A$12,'List of Ledgers '!$G:$G,'P&L'!Q6) -> 0 | R12: =SUMIFS('List of Ledgers '!$Q:$Q,'List of Ledgers '!$F:$F,'P&L'!$A$12,'List of Ledgers '!$G:$G,'P&L'!R6) -> 0 | S12: =SUMIFS('List of Ledgers '!$Q:$Q,'List of Ledgers '!$F:$F,'P&L'!$A$12,'List of Ledgers '!$G:$G,'P&L'!S6) -> 0 | T12: =SUMIFS('List of Ledgers '!$Q:$Q,'List of Ledgers '!$F:$F,'P&L'!$A$12,'List of Ledgers '!$G:$G,'P&L'!T6) -> 0 | U12: =SUMIFS('List of Ledgers '!$Q:$Q,'List of Ledgers '!$F:$F,'P&L'!$A$12,'List of Ledgers '!$G:$G,'P&L'!U6) -> 811934.68 | V12: =SUM(N12:U12) -> 1008120.6 | X12: =V12+W12 -> 1008120.6 | Y12: =V12-X12 -> 0
A13: Export charges | B13: =SUMIFS('List of Ledgers '!$L:$L,'List of Ledgers '!$F:$F,'P&L'!$A13,'List of Ledgers '!$G:$G,'P&L'!B$6) -> 0 | C13: =SUMIFS('List of Ledgers '!$L:$L,'List of Ledgers '!$F:$F,'P&L'!$A13,'List of Ledgers '!$G:$G,'P&L'!C$6) -> 0 | D13: =SUMIFS('List of Ledgers '!$L:$L,'List of Ledgers '!$F:$F,'P&L'!$A13,'List of Ledgers '!$G:$G,'P&L'!D$6) -> -16833 | E13: =SUMIFS('List of Ledgers '!$L:$L,'List of Ledgers '!$F:$F,'P&L'!$A13,'List of Ledgers '!$G:$G,'P&L'!E$6) -> 0 | F13: =SUMIFS('List of Ledgers '!$L:$L,'List of Ledgers '!$F:$F,'P&L'!$A13,'List of Ledgers '!$G:$G,'P&L'!F$6) -> 0 | G13: =SUMIFS('List of Ledgers '!$L:$L,'List of Ledgers '!$F:$F,'P&L'!$A13,'List of Ledgers '!$G:$G,'P&L'!G$6) -> 0 | H13: =SUMIFS('List of Ledgers '!$L:$L,'List of Ledgers '!$F:$F,'P&L'!$A13,'List of Ledgers '!$G:$G,'P&L'!H$6) -> 0 | I13: =SUMIFS('List of Ledgers '!$L:$L,'List of Ledgers '!$F:$F,'P&L'!$A13,'List of Ledgers '!$G:$G,'P&L'!I$6) -> 0 | J13: =SUM(B13:I13) -> -16833 | K13: =SUMIFS('List of Ledgers '!$L:$L,'List of Ledgers '!$F:$F,'P&L'!$A13,'List of Ledgers '!$G:$G,'P&L'!K$6) -> 0 | L13: =J13+K13 -> -16833 | N13: =SUMIFS('List of Ledgers '!$Q:$Q,'List of Ledgers '!$F:$F,'P&L'!$A$13,'List of Ledgers '!$G:$G,'P&L'!N6) -> 0 | O13: =SUMIFS('List of Ledgers '!$Q:$Q,'List of Ledgers '!$F:$F,'P&L'!$A$13,'List of Ledgers '!$G:$G,'P&L'!O6) -> 0 | P13: =SUMIFS('List of Ledgers '!$Q:$Q,'List of Ledgers '!$F:$F,'P&L'!$A$13,'List of Ledgers '!$G:$G,'P&L'!P6) -> 1575 | Q13: =SUMIFS('List of Ledgers '!$Q:$Q,'List of Ledgers '!$F:$F,'P&L'!$A$13,'List of Ledgers '!$G:$G,'P&L'!Q6) -> 0 | R13: =SUMIFS('List of Ledgers '!$Q:$Q,'List of Ledgers '!$F:$F,'P&L'!$A$13,'List of Ledgers '!$G:$G,'P&L'!R6) -> 0 | S13: =SUMIFS('List of Ledgers '!$Q:$Q,'List of Ledgers '!$F:$F,'P&L'!$A$13,'List of Ledgers '!$G:$G,'P&L'!S6) -> 0 | T13: =SUMIFS('List of Ledgers '!$Q:$Q,'List of Ledgers '!$F:$F,'P&L'!$A$13,'List of Ledgers '!$G:$G,'P&L'!T6) -> 0 | U13: =SUMIFS('List of Ledgers '!$Q:$Q,'List of Ledgers '!$F:$F,'P&L'!$A$13,'List of Ledgers '!$G:$G,'P&L'!U6) -> 0 | V13: =SUM(N13:U13) -> 1575 | X13: =V13+W13 -> 1575 | Y13: =V13-X13 -> 0
A14: Insurance expenses | B14: =SUMIFS('List of Ledgers '!$L:$L,'List of Ledgers '!$F:$F,'P&L'!$A14,'List of Ledgers '!$G:$G,'P&L'!B$6) -> 0 | C14: =SUMIFS('List of Ledgers '!$L:$L,'List of Ledgers '!$F:$F,'P&L'!$A14,'List of Ledgers '!$G:$G,'P&L'!C$6) -> 0 | D14: =SUMIFS('List of Ledgers '!$L:$L,'List of Ledgers '!$F:$F,'P&L'!$A14,'List of Ledgers '!$G:$G,'P&L'!D$6) -> 14837 | E14: =SUMIFS('List of Ledgers '!$L:$L,'List of Ledgers '!$F:$F,'P&L'!$A14,'List of Ledgers '!$G:$G,'P&L'!E$6) -> 0 | F14: =SUMIFS('List of Ledgers '!$L:$L,'List of Ledgers '!$F:$F,'P&L'!$A14,'List of Ledgers '!$G:$G,'P&L'!F$6) -> 0 | G14: =SUMIFS('List of Ledgers '!$L:$L,'List of Ledgers '!$F:$F,'P&L'!$A14,'List of Ledgers '!$G:$G,'P&L'!G$6) -> 0 | H14: =SUMIFS('List of Ledgers '!$L:$L,'List of Ledgers '!$F:$F,'P&L'!$A14,'List of Ledgers '!$G:$G,'P&L'!H$6) -> 0 | I14: =SUMIFS('List of Ledgers '!$L:$L,'List of Ledgers '!$F:$F,'P&L'!$A14,'List of Ledgers '!$G:$G,'P&L'!I$6) -> 0 | J14: =SUM(B14:I14) -> 14837 | K14: =SUMIFS('List of Ledgers '!$L:$L,'List of Ledgers '!$F:$F,'P&L'!$A14,'List of Ledgers '!$G:$G,'P&L'!K$6) -> 0 | L14: =J14+K14 -> 14837 | N14: =SUMIFS('List of Ledgers '!$Q:$Q,'List of Ledgers '!$F:$F,'P&L'!$A$14,'List of Ledgers '!$G:$G,'P&L'!N6,'List of Ledgers '!E:E,'P&L'!A9) -> 0 | O14: =SUMIFS('List of Ledgers '!$Q:$Q,'List of Ledgers '!$F:$F,'P&L'!$A$14,'List of Ledgers '!$G:$G,'P&L'!O6,'List of Ledgers '!F:F,'P&L'!B9) -> 0 | P14: =SUMIFS('List of Ledgers '!$Q:$Q,'List of Ledgers '!$F:$F,'P&L'!$A$14,'List of Ledgers '!$G:$G,'P&L'!P6,'List of Ledgers '!E:E,'P&L'!A9) -> 177005 | Q14: =SUMIFS('List of Ledgers '!$Q:$Q,'List of Ledgers '!$F:$F,'P&L'!$A$14,'List of Ledgers '!$G:$G,'P&L'!Q6) -> 0 | R14: =SUMIFS('List of Ledgers '!$Q:$Q,'List of Ledgers '!$F:$F,'P&L'!$A$14,'List of Ledgers '!$G:$G,'P&L'!R6) -> 0 | S14: =SUMIFS('List of Ledgers '!$Q:$Q,'List of Ledgers '!$F:$F,'P&L'!$A$14,'List of Ledgers '!$G:$G,'P&L'!S6,'List of Ledgers '!H:H,'P&L'!D9) -> 0 | T14: =SUMIFS('List of Ledgers '!$Q:$Q,'List of Ledgers '!$F:$F,'P&L'!$A$14,'List of Ledgers '!$G:$G,'P&L'!T6) -> 0 | U14: =SUMIFS('List of Ledgers '!$Q:$Q,'List of Ledgers '!$F:$F,'P&L'!$A$14,'List of Ledgers '!$G:$G,'P&L'!U6) -> 0 | V14: =SUM(N14:U14) -> 177005 | X14: =V14+W14 -> 177005 | Y14: =V14-X14 -> 0
Y15: =V15-X15 -> 0
A16: Gross margin | B16: =B7-B8-B9 -> 0 | C16: =C7-C8-C9 -> 2.910383e-11 | D16: =D7-D8-D9 -> -96420.47 | E16: =E7-E8-E9 -> 0 | F16: =F7-F8-F9 -> 0 | G16: =G7-G8-G9 -> -35050 | H16: =H7-H8-H9 -> 0 | I16: =I7-I8-I9 -> 3336179.8 | ... L16: =L7-L8-L9 -> 3204709.3 | N16: =N7-N8-N9 -> -61053.05 | O16: =O7-O8-O9 -> 328384.55 | P16: =P7-P8-P9 -> 2881002.3 | Q16: =Q7-Q8-Q9 -> 0 | R16: =R7-R8-R9 -> 0 | S16: =S7-S8-S9 -> -77760 | T16: =T7-T8-T9 -> 0 | U16: =U7-U8-U9 -> 5640355.4 | V16: =V7-V8-V9 -> 8710929.3 | W16: =W7-W8 -> 0 | X16: =X7-X8-X9 -> 8710929.3 | Y16: =V16-X16 -> 0
A17: Gross margin % | B17: =IFERROR(B16/B7,0) -> 0 | C17: =IFERROR(C16/C7,0) -> 1.0235315e-15 | D17: =IFERROR(D16/D7,0) -> 0 | E17: =IFERROR(E16/E7,0) -> 0 | F17: =IFERROR(F16/F7,0) -> 0 | G17: =IFERROR(G16/G7,0) -> 0 | H17: =IFERROR(H16/H7,0) -> 0 | I17: =IFERROR(I16/I7,0) -> 0.04447491 | ... L17: =IFERROR(L16/L7,0) -> 0.042706077 | N17: =IFERROR(N16/N7,0) -> -0.034478633 | O17: =IFERROR(O16/O7,0) -> 0.39198862 | P17: =IFERROR(P16/P7,0) -> 0.027226701 | Q17: =IFERROR(Q16/Q7,0) -> 0 | R17: =IFERROR(R16/R7,0) -> 0 | S17: =IFERROR(S16/S7,0) -> 0 | T17: =IFERROR(T16/T7,0) -> 0 | U17: =IFERROR(U16/U7,0) -> 0.04704539 | ... X17: =IFERROR(X16/X7,0) -> 0.038153019 | Y17: =V17-X17 -> 0
A18: Gross margin % (previous month) | B18: 0 | C18: -3.20414 | D18: 0 | E18: 0 | F18: 0 | G18: 0 | H18: 0 | I18: 0.080499262 | J18: 0.07626975 | K18: 0 | L18: 0.07626975 | N18: -0.034478633 | O18: 0.44505527 | P18: 0.0092295017 | Q18: 0 | R18: 0 | S18: 0 | T18: 0 | U18: 0.10579676 | V18: 0.041737929 | W18: 0 | X18: 0.041737929 | Y18: =V18-X18 -> 0
Y19: =V19-X19 -> 0
A20: Indirect Income | B20: =SUM(B21:B27) -> 0 | C20: =SUM(C21:C27) -> 0 | D20: =SUM(D21:D27) -> 17000000 | E20: =SUM(E21:E27) -> 0 | F20: =SUM(F21:F27) -> 0 | G20: =SUM(G21:G27) -> 0 | H20: =SUM(H21:H27) -> 200000 | I20: =SUM(I21:I27) -> 0 | J20: =SUM(B20:I20) -> 17200000 | K20: =SUM(K21:K27) -> 0 | L20: =SUM(L21:L27) -> 17200000 | N20: =SUM(N21:N28) -> 0 | O20: =SUM(O21:O28) -> 0 | P20: =SUM(P21:P28) -> 17548744 | Q20: =SUM(Q21:Q28) -> 0 | R20: =SUM(R21:R28) -> 0 | S20: =SUM(S21:S28) -> 691117.44 | T20: =SUM(T21:T28) -> 200000 | U20: =SUM(U21:U28) -> 0 | ... W20: =SUM(W21:W28) -> -211354.2 | X20: =SUM(V20:W20) -> 18228507 | Y20: =V20-X20 -> 211354.2
A21: Foreign Exchange Gain | B21: =SUMIFS('List of Ledgers '!$L:$L,'List of Ledgers '!$F:$F,'P&L'!$A$21,'List of Ledgers '!$G:$G,'P&L'!B6) -> 0 | C21: =SUMIFS('List of Ledgers '!$L:$L,'List of Ledgers '!$F:$F,'P&L'!$A$21,'List of Ledgers '!$G:$G,'P&L'!C6) -> 0 | D21: =SUMIFS('List of Ledgers '!$L:$L,'List of Ledgers '!$F:$F,'P&L'!$A$21,'List of Ledgers '!$G:$G,'P&L'!D6) -> 0 | E21: =SUMIFS('List of Ledgers '!$L:$L,'List of Ledgers '!$F:$F,'P&L'!$A$21,'List of Ledgers '!$G:$G,'P&L'!E6) -> 0 | F21: =SUMIFS('List of Ledgers '!$L:$L,'List of Ledgers '!$F:$F,'P&L'!$A$21,'List of Ledgers '!$G:$G,'P&L'!F6) -> 0 | G21: =-SUMIFS('List of Ledgers '!$L:$L,'List of Ledgers '!$F:$F,'P&L'!$A$21,'List of Ledgers '!$G:$G,'P&L'!G6) -> 0 | H21: =SUMIFS('List of Ledgers '!$L:$L,'List of Ledgers '!$F:$F,'P&L'!$A$21,'List of Ledgers '!$G:$G,'P&L'!H6) -> 0 | I21: =SUMIFS('List of Ledgers '!$L:$L,'List of Ledgers '!$F:$F,'P&L'!$A$21,'List of Ledgers '!$G:$G,'P&L'!I6) -> 0 | J21: =SUM(B21:I21) -> 0 | K21: =SUMIFS('List of Ledgers '!$L:$L,'List of Ledgers '!$F:$F,'P&L'!$A$21,'List of Ledgers '!$G:$G,'P&L'!K6) -> 0 | L21: =J21+K21 -> 0 | N21: =-SUMIFS('List of Ledgers '!$Q:$Q,'List of Ledgers '!$F:$F,'P&L'!$A$21,'List of Ledgers '!$G:$G,'P&L'!N6) -> 0 | O21: =-SUMIFS('List of Ledgers '!$Q:$Q,'List of Ledgers '!$F:$F,'P&L'!$A$21,'List of Ledgers '!$G:$G,'P&L'!O6) -> 0 | P21: =-SUMIFS('List of Ledgers '!$Q:$Q,'List of Ledgers '!$F:$F,'P&L'!$A$21,'List of Ledgers '!$G:$G,'P&L'!P6) -> 0 | Q21: =-SUMIFS('List of Ledgers '!$Q:$Q,'List of Ledgers '!$F:$F,'P&L'!$A$21,'List of Ledgers '!$G:$G,'P&L'!Q6) -> 0 | R21: =-SUMIFS('List of Ledgers '!$Q:$Q,'List of Ledgers '!$F:$F,'P&L'!$A$21,'List of Ledgers '!$G:$G,'P&L'!R6) -> 0 | S21: =-SUMIFS('List of Ledgers '!$Q:$Q,'List of Ledgers '!$F:$F,'P&L'!$A$21,'List of Ledgers '!$G:$G,'P&L'!S6) -> 566542.44 | T21: =-SUMIFS('List of Ledgers '!$Q:$Q,'List of Ledgers '!$F:$F,'P&L'!$A$21,'List of Ledgers '!$G:$G,'P&L'!T6) -> 0 | U21: =-SUMIFS('List of Ledgers '!$Q:$Q,'List of Ledgers '!$F:$F,'P&L'!$A$21,'List of Ledgers '!$G:$G,'P&L'!U6) -> 0 | V21: =SUM(N21:U21) -> 566542.44 | W21: =-SUMIFS('List of Ledgers '!$Q:$Q,'List of Ledgers '!$F:$F,'P&L'!$A$21,'List of Ledgers '!$G:$G,'P&L'!W6) -> 0 | X21: =SUM(V21:W21) -> 566542.44 | Y21: =V21-X21 -> 0
A22: Exhibtion Income | B22: =SUMIFS('List of Ledgers '!$L:$L,'List of Ledgers '!$F:$F,'P&L'!$A$22,'List of Ledgers '!$G:$G,'P&L'!B6) -> 0 | C22: =SUMIFS('List of Ledgers '!$L:$L,'List of Ledgers '!$F:$F,'P&L'!$A$22,'List of Ledgers '!$G:$G,'P&L'!C6) -> 0 | D22: =SUMIFS('List of Ledgers '!$L:$L,'List of Ledgers '!$F:$F,'P&L'!$A$22,'List of Ledgers '!$G:$G,'P&L'!D6) -> 0 | E22: =SUMIFS('List of Ledgers '!$L:$L,'List of Ledgers '!$F:$F,'P&L'!$A$22,'List of Ledgers '!$G:$G,'P&L'!E6) -> 0 | F22: =SUMIFS('List of Ledgers '!$L:$L,'List of Ledgers '!$F:$F,'P&L'!$A$22,'List of Ledgers '!$G:$G,'P&L'!F6) -> 0 | G22: =SUMIFS('List of Ledgers '!$L:$L,'List of Ledgers '!$F:$F,'P&L'!$A$22,'List of Ledgers '!$G:$G,'P&L'!G6) -> 0 | H22: =-SUMIFS('List of Ledgers '!$L:$L,'List of Ledgers '!$F:$F,'P&L'!$A$22,'List of Ledgers '!$G:$G,'P&L'!H6) -> 200000 | I22: =SUMIFS('List of Ledgers '!$L:$L,'List of Ledgers '!$F:$F,'P&L'!$A$22,'List of Ledgers '!$G:$G,'P&L'!I6) -> 0 | J22: =SUM(B22:I22) -> 200000 | K22: =SUMIFS('List of Ledgers '!$L:$L,'List of Ledgers '!$F:$F,'P&L'!$A$22,'List of Ledgers '!$G:$G,'P&L'!K6) -> 0 | L22: =J22+K22 -> 200000 | N22: =-SUMIFS('List of Ledgers '!$Q:$Q,'List of Ledgers '!$F:$F,'P&L'!$A$22,'List of Ledgers '!$G:$G,'P&L'!N6) -> 0 | O22: =-SUMIFS('List of Ledgers '!$Q:$Q,'List of Ledgers '!$F:$F,'P&L'!$A$22,'List of Ledgers '!$G:$G,'P&L'!O6) -> 0 | P22: =-SUMIFS('List of Ledgers '!$Q:$Q,'List of Ledgers '!$F:$F,'P&L'!$A$22,'List of Ledgers '!$G:$G,'P&L'!P6) -> 0 | Q22: =-SUMIFS('List of Ledgers '!$Q:$Q,'List of Ledgers '!$F:$F,'P&L'!$A$22,'List of Ledgers '!$G:$G,'P&L'!Q6) -> 0 | R22: =-SUMIFS('List of Ledgers '!$Q:$Q,'List of Ledgers '!$F:$F,'P&L'!$A$22,'List of Ledgers '!$G:$G,'P&L'!R6) -> 0 | S22: =-SUMIFS('List of Ledgers '!$Q:$Q,'List of Ledgers '!$F:$F,'P&L'!$A$22,'List of Ledgers '!$G:$G,'P&L'!S6) -> 0 | T22: =-SUMIFS('List of Ledgers '!$Q:$Q,'List of Ledgers '!$F:$F,'P&L'!$A$22,'List of Ledgers '!$G:$G,'P&L'!T6) -> 200000 | U22: =-SUMIFS('List of Ledgers '!$Q:$Q,'List of Ledgers '!$F:$F,'P&L'!$A$22,'List of Ledgers '!$G:$G,'P&L'!U6) -> 0 | V22: =SUM(N22:U22) -> 200000 | W22: =-SUMIFS('List of Ledgers '!$Q:$Q,'List of Ledgers '!$F:$F,'P&L'!$A$21,'List of Ledgers '!$G:$G,'P&L'!W7) -> 0
A23: Commission | B23: =SUMIFS('List of Ledgers '!$L:$L,'List of Ledgers '!$F:$F,'P&L'!$A$23,'List of Ledgers '!$G:$G,'P&L'!B6) -> 0 | C23: =SUMIFS('List of Ledgers '!$L:$L,'List of Ledgers '!$F:$F,'P&L'!$A$23,'List of Ledgers '!$G:$G,'P&L'!C6) -> 0 | D23: =-SUMIFS('List of Ledgers '!$L:$L,'List of Ledgers '!$F:$F,'P&L'!$A$23,'List of Ledgers '!$G:$G,'P&L'!D6) -> 17000000 | E23: =SUMIFS('List of Ledgers '!$L:$L,'List of Ledgers '!$F:$F,'P&L'!$A$23,'List of Ledgers '!$G:$G,'P&L'!E6) -> 0 | F23: =SUMIFS('List of Ledgers '!$L:$L,'List of Ledgers '!$F:$F,'P&L'!$A$23,'List of Ledgers '!$G:$G,'P&L'!F6) -> 0 | G23: =SUMIFS('List of Ledgers '!$L:$L,'List of Ledgers '!$F:$F,'P&L'!$A$23,'List of Ledgers '!$G:$G,'P&L'!G6) -> 0 | H23: =SUMIFS('List of Ledgers '!$L:$L,'List of Ledgers '!$F:$F,'P&L'!$A$23,'List of Ledgers '!$G:$G,'P&L'!H6) -> 0 | I23: =SUMIFS('List of Ledgers '!$L:$L,'List of Ledgers '!$F:$F,'P&L'!$A$23,'List of Ledgers '!$G:$G,'P&L'!I6) -> 0 | J23: =SUM(B23:I23) -> 17000000 | K23: =SUMIFS('List of Ledgers '!$L:$L,'List of Ledgers '!$F:$F,'P&L'!$A$21,'List of Ledgers '!$G:$G,'P&L'!K7) -> 0 | L23: =J23+K23 -> 17000000 | N23: =-SUMIFS('List of Ledgers '!$Q:$Q,'List of Ledgers '!$F:$F,'P&L'!$A$23,'List of Ledgers '!$G:$G,'P&L'!N6) -> 0 | O23: =-SUMIFS('List of Ledgers '!$Q:$Q,'List of Ledgers '!$F:$F,'P&L'!$A$23,'List of Ledgers '!$G:$G,'P&L'!O6) -> 0 | P23: =-SUMIFS('List of Ledgers '!$Q:$Q,'List of Ledgers '!$F:$F,'P&L'!$A$23,'List of Ledgers '!$G:$G,'P&L'!P6) -> 17548744 | Q23: =-SUMIFS('List of Ledgers '!$Q:$Q,'List of Ledgers '!$F:$F,'P&L'!$A$23,'List of Ledgers '!$G:$G,'P&L'!Q6) -> 0 | R23: =-SUMIFS('List of Ledgers '!$Q:$Q,'List of Ledgers '!$F:$F,'P&L'!$A$23,'List of Ledgers '!$G:$G,'P&L'!R6) -> 0 | S23: =-SUMIFS('List of Ledgers '!$Q:$Q,'List of Ledgers '!$F:$F,'P&L'!$A$23,'List of Ledgers '!$G:$G,'P&L'!S6) -> 0 | T23: =-SUMIFS('List of Ledgers '!$Q:$Q,'List of Ledgers '!$F:$F,'P&L'!$A$23,'List of Ledgers '!$G:$G,'P&L'!T6) -> 0 | U23: =-SUMIFS('List of Ledgers '!$Q:$Q,'List of Ledgers '!$F:$F,'P&L'!$A$23,'List of Ledgers '!$G:$G,'P&L'!U6) -> 0 | V23: =SUM(N23:U23) -> 17548744 | W23: =-SUMIFS('List of Ledgers '!$Q:$Q,'List of Ledgers '!$F:$F,'P&L'!$A$23,'List of Ledgers '!$G:$G,'P&L'!W6) -> 0 | X23: =SUM(V23:W23) -> 17548744 | Y23: =V23-X23 -> 0
A24: Dividend | B24: =SUMIFS('List of Ledgers '!$L:$L,'List of Ledgers '!$F:$F,'P&L'!$A$24,'List of Ledgers '!$G:$G,'P&L'!B6) -> 0 | C24: =SUMIFS('List of Ledgers '!$L:$L,'List of Ledgers '!$F:$F,'P&L'!$A$24,'List of Ledgers '!$G:$G,'P&L'!C6) -> 0 | D24: =SUMIFS('List of Ledgers '!$L:$L,'List of Ledgers '!$F:$F,'P&L'!$A$24,'List of Ledgers '!$G:$G,'P&L'!D6) -> 0 | E24: =SUMIFS('List of Ledgers '!$L:$L,'List of Ledgers '!$F:$F,'P&L'!$A$24,'List of Ledgers '!$G:$G,'P&L'!E6) -> 0 | F24: =SUMIFS('List of Ledgers '!$L:$L,'List of Ledgers '!$F:$F,'P&L'!$A$24,'List of Ledgers '!$G:$G,'P&L'!F6) -> 0 | G24: =SUMIFS('List of Ledgers '!$L:$L,'List of Ledgers '!$F:$F,'P&L'!$A$24,'List of Ledgers '!$G:$G,'P&L'!G6) -> 0 | H24: =SUMIFS('List of Ledgers '!$L:$L,'List of Ledgers '!$F:$F,'P&L'!$A$24,'List of Ledgers '!$G:$G,'P&L'!H6) -> 0 | I24: =SUMIFS('List of Ledgers '!$L:$L,'List of Ledgers '!$F:$F,'P&L'!$A$24,'List of Ledgers '!$G:$G,'P&L'!I6) -> 0 | J24: =SUM(B24:I24) -> 0 | K24: =SUMIFS('List of Ledgers '!$L:$L,'List of Ledgers '!$F:$F,'P&L'!$A$21,'List of Ledgers '!$G:$G,'P&L'!K8) -> 0 | L24: =J24+K24 -> 0 | N24: =-SUMIFS('List of Ledgers '!$Q:$Q,'List of Ledgers '!$F:$F,'P&L'!$A$24,'List of Ledgers '!$G:$G,'P&L'!N6) -> 0 | O24: =-SUMIFS('List of Ledgers '!$Q:$Q,'List of Ledgers '!$F:$F,'P&L'!$A$24,'List of Ledgers '!$G:$G,'P&L'!O6) -> 0 | P24: =-SUMIFS('List of Ledgers '!$Q:$Q,'List of Ledgers '!$F:$F,'P&L'!$A$24,'List of Ledgers '!$G:$G,'P&L'!P6) -> 0 | Q24: =-SUMIFS('List of Ledgers '!$Q:$Q,'List of Ledgers '!$F:$F,'P&L'!$A$24,'List of Ledgers '!$G:$G,'P&L'!Q6) -> 0 | R24: =-SUMIFS('List of Ledgers '!$Q:$Q,'List of Ledgers '!$F:$F,'P&L'!$A$24,'List of Ledgers '!$G:$G,'P&L'!R6) -> 0 | S24: =-SUMIFS('List of Ledgers '!$Q:$Q,'List of Ledgers '!$F:$F,'P&L'!$A$24,'List of Ledgers '!$G:$G,'P&L'!S6) -> 0 | T24: =-SUMIFS('List of Ledgers '!$Q:$Q,'List of Ledgers '!$F:$F,'P&L'!$A$24,'List of Ledgers '!$G:$G,'P&L'!T6) -> 0 | U24: =-SUMIFS('List of Ledgers '!$Q:$Q,'List of Ledgers '!$F:$F,'P&L'!$A$24,'List of Ledgers '!$G:$G,'P&L'!U6) -> 0 | V24: =SUM(N24:U24) -> 0 | W24: =-SUMIFS('List of Ledgers '!$Q:$Q,'List of Ledgers '!$F:$F,'P&L'!$A$24,'List of Ledgers '!$G:$G,'P&L'!W6) -> 10487 | X24: =SUM(V24:W24) -> 10487 | Y24: =V24-X24 -> -10487
A25: Interest Income | B25: =SUMIFS('List of Ledgers '!$L:$L,'List of Ledgers '!$F:$F,'P&L'!$A$25,'List of Ledgers '!$G:$G,'P&L'!B6) -> 0 | C25: =SUMIFS('List of Ledgers '!$L:$L,'List of Ledgers '!$F:$F,'P&L'!$A$25,'List of Ledgers '!$G:$G,'P&L'!C6) -> 0 | D25: =SUMIFS('List of Ledgers '!$L:$L,'List of Ledgers '!$F:$F,'P&L'!$A$25,'List of Ledgers '!$G:$G,'P&L'!D6) -> 0 | E25: =SUMIFS('List of Ledgers '!$L:$L,'List of Ledgers '!$F:$F,'P&L'!$A$25,'List of Ledgers '!$G:$G,'P&L'!E6) -> 0 | F25: =SUMIFS('List of Ledgers '!$L:$L,'List of Ledgers '!$F:$F,'P&L'!$A$25,'List of Ledgers '!$G:$G,'P&L'!F6) -> 0 | G25: =SUMIFS('List of Ledgers '!$L:$L,'List of Ledgers '!$F:$F,'P&L'!$A$25,'List of Ledgers '!$G:$G,'P&L'!G6) -> 0 | H25: =SUMIFS('List of Ledgers '!$L:$L,'List of Ledgers '!$F:$F,'P&L'!$A$25,'List of Ledgers '!$G:$G,'P&L'!H6) -> 0 | I25: =SUMIFS('List of Ledgers '!$L:$L,'List of Ledgers '!$F:$F,'P&L'!$A$25,'List of Ledgers '!$G:$G,'P&L'!I6) -> 0 | J25: =SUM(B25:I25) -> 0 | K25: =SUMIFS('List of Ledgers '!$L:$L,'List of Ledgers '!$F:$F,'P&L'!$A$21,'List of Ledgers '!$G:$G,'P&L'!K9) -> 0 | L25: =J25+K25 -> 0 | N25: =-SUMIFS('List of Ledgers '!$Q:$Q,'List of Ledgers '!$F:$F,'P&L'!$A$25,'List of Ledgers '!$G:$G,'P&L'!N6) -> 0 | O25: =-SUMIFS('List of Ledgers '!$Q:$Q,'List of Ledgers '!$F:$F,'P&L'!$A$25,'List of Ledgers '!$G:$G,'P&L'!O6) -> 0 | P25: =-SUMIFS('List of Ledgers '!$Q:$Q,'List of Ledgers '!$F:$F,'P&L'!$A$25,'List of Ledgers '!$G:$G,'P&L'!P6) -> 0 | Q25: =-SUMIFS('List of Ledgers '!$Q:$Q,'List of Ledgers '!$F:$F,'P&L'!$A$25,'List of Ledgers '!$G:$G,'P&L'!Q6) -> 0 | R25: =-SUMIFS('List of Ledgers '!$Q:$Q,'List of Ledgers '!$F:$F,'P&L'!$A$25,'List of Ledgers '!$G:$G,'P&L'!R6) -> 0 | S25: =-SUMIFS('List of Ledgers '!$Q:$Q,'List of Ledgers '!$F:$F,'P&L'!$A$25,'List of Ledgers '!$G:$G,'P&L'!S6) -> 124575 | T25: =-SUMIFS('List of Ledgers '!$Q:$Q,'List of Ledgers '!$F:$F,'P&L'!$A$25,'List of Ledgers '!$G:$G,'P&L'!T6) -> 0 | U25: =-SUMIFS('List of Ledgers '!$Q:$Q,'List of Ledgers '!$F:$F,'P&L'!$A$25,'List of Ledgers '!$G:$G,'P&L'!U6) -> 0 | V25: =SUM(N25:U25) -> 124575 | W25: =-SUMIFS('List of Ledgers '!$Q:$Q,'List of Ledgers '!$F:$F,'P&L'!$A$25,'List of Ledgers '!$G:$G,'P&L'!W6) -> 0 | X25: =SUM(V25:W25) -> 124575 | Y25: =V25-X25 -> 0
A26: Short term Capital Gain | B26: =SUMIFS('List of Ledgers '!$L:$L,'List of Ledgers '!$F:$F,'P&L'!$A$26,'List of Ledgers '!$G:$G,'P&L'!B6) -> 0 | C26: =SUMIFS('List of Ledgers '!$L:$L,'List of Ledgers '!$F:$F,'P&L'!$A$26,'List of Ledgers '!$G:$G,'P&L'!C6) -> 0 | D26: =SUMIFS('List of Ledgers '!$L:$L,'List of Ledgers '!$F:$F,'P&L'!$A$26,'List of Ledgers '!$G:$G,'P&L'!D6) -> 0 | E26: =SUMIFS('List of Ledgers '!$L:$L,'List of Ledgers '!$F:$F,'P&L'!$A$26,'List of Ledgers '!$G:$G,'P&L'!E6) -> 0 | F26: =SUMIFS('List of Ledgers '!$L:$L,'List of Ledgers '!$F:$F,'P&L'!$A$26,'List of Ledgers '!$G:$G,'P&L'!F6) -> 0 | G26: =SUMIFS('List of Ledgers '!$L:$L,'List of Ledgers '!$F:$F,'P&L'!$A$26,'List of Ledgers '!$G:$G,'P&L'!G6) -> 0 | H26: =SUMIFS('List of Ledgers '!$L:$L,'List of Ledgers '!$F:$F,'P&L'!$A$26,'List of Ledgers '!$G:$G,'P&L'!H6) -> 0 | I26: =SUMIFS('List of Ledgers '!$L:$L,'List of Ledgers '!$F:$F,'P&L'!$A$26,'List of Ledgers '!$G:$G,'P&L'!I6) -> 0 | J26: =SUM(B26:I26) -> 0 | K26: =SUMIFS('List of Ledgers '!$L:$L,'List of Ledgers '!$F:$F,'P&L'!$A$21,'List of Ledgers '!$G:$G,'P&L'!K10) -> 0 | L26: =J26+K26 -> 0 | N26: =-SUMIFS('List of Ledgers '!$Q:$Q,'List of Ledgers '!$F:$F,'P&L'!$A$26,'List of Ledgers '!$G:$G,'P&L'!N6) -> 0 | O26: =-SUMIFS('List of Ledgers '!$Q:$Q,'List of Ledgers '!$F:$F,'P&L'!$A$26,'List of Ledgers '!$G:$G,'P&L'!O6) -> 0 | P26: =-SUMIFS('List of Ledgers '!$Q:$Q,'List of Ledgers '!$F:$F,'P&L'!$A$26,'List of Ledgers '!$G:$G,'P&L'!P6) -> 0 | Q26: =-SUMIFS('List of Ledgers '!$Q:$Q,'List of Ledgers '!$F:$F,'P&L'!$A$26,'List of Ledgers '!$G:$G,'P&L'!Q6) -> 0 | R26: =-SUMIFS('List of Ledgers '!$Q:$Q,'List of Ledgers '!$F:$F,'P&L'!$A$26,'List of Ledgers '!$G:$G,'P&L'!R6) -> 0 | S26: =-SUMIFS('List of Ledgers '!$Q:$Q,'List of Ledgers '!$F:$F,'P&L'!$A$26,'List of Ledgers '!$G:$G,'P&L'!S6) -> 0 | T26: =-SUMIFS('List of Ledgers '!$Q:$Q,'List of Ledgers '!$F:$F,'P&L'!$A$26,'List of Ledgers '!$G:$G,'P&L'!T6) -> 0 | U26: =-SUMIFS('List of Ledgers '!$Q:$Q,'List of Ledgers '!$F:$F,'P&L'!$A$26,'List of Ledgers '!$G:$G,'P&L'!U6) -> 0 | V26: =SUM(N26:U26) -> 0 | W26: =-SUMIFS('List of Ledgers '!$Q:$Q,'List of Ledgers '!$F:$F,'P&L'!$A$26,'List of Ledgers '!$G:$G,'P&L'!W6) -> 465583.48 | X26: =SUM(V26:W26) -> 465583.48 | Y26: =V26-X26 -> -465583.48
A27: Profit on sale of Investment | B27: =SUMIFS('List of Ledgers '!$L:$L,'List of Ledgers '!$F:$F,'P&L'!$A$27,'List of Ledgers '!$G:$G,'P&L'!B6) -> 0 | C27: =SUMIFS('List of Ledgers '!$L:$L,'List of Ledgers '!$F:$F,'P&L'!$A$27,'List of Ledgers '!$G:$G,'P&L'!C6) -> 0 | D27: =SUMIFS('List of Ledgers '!$L:$L,'List of Ledgers '!$F:$F,'P&L'!$A$27,'List of Ledgers '!$G:$G,'P&L'!D6) -> 0 | E27: =SUMIFS('List of Ledgers '!$L:$L,'List of Ledgers '!$F:$F,'P&L'!$A$27,'List of Ledgers '!$G:$G,'P&L'!E6) -> 0 | F27: =SUMIFS('List of Ledgers '!$L:$L,'List of Ledgers '!$F:$F,'P&L'!$A$27,'List of Ledgers '!$G:$G,'P&L'!F6) -> 0 | G27: =SUMIFS('List of Ledgers '!$L:$L,'List of Ledgers '!$F:$F,'P&L'!$A$27,'List of Ledgers '!$G:$G,'P&L'!G6) -> 0 | H27: =SUMIFS('List of Ledgers '!$L:$L,'List of Ledgers '!$F:$F,'P&L'!$A$27,'List of Ledgers '!$G:$G,'P&L'!H6) -> 0 | I27: =SUMIFS('List of Ledgers '!$L:$L,'List of Ledgers '!$F:$F,'P&L'!$A$27,'List of Ledgers '!$G:$G,'P&L'!I6) -> 0 | J27: =SUM(B27:I27) -> 0 | K27: =SUMIFS('List of Ledgers '!$L:$L,'List of Ledgers '!$F:$F,'P&L'!$A$21,'List of Ledgers '!$G:$G,'P&L'!K11) -> 0 | L27: =J27+K27 -> 0 | N27: =-SUMIFS('List of Ledgers '!$Q:$Q,'List of Ledgers '!$F:$F,'P&L'!$A$27,'List of Ledgers '!$G:$G,'P&L'!N6) -> 0 | O27: =-SUMIFS('List of Ledgers '!$Q:$Q,'List of Ledgers '!$F:$F,'P&L'!$A$27,'List of Ledgers '!$G:$G,'P&L'!O6) -> 0 | P27: =-SUMIFS('List of Ledgers '!$Q:$Q,'List of Ledgers '!$F:$F,'P&L'!$A$27,'List of Ledgers '!$G:$G,'P&L'!P6) -> 0 | Q27: =-SUMIFS('List of Ledgers '!$Q:$Q,'List of Ledgers '!$F:$F,'P&L'!$A$27,'List of Ledgers '!$G:$G,'P&L'!Q6) -> 0 | R27: =-SUMIFS('List of Ledgers '!$Q:$Q,'List of Ledgers '!$F:$F,'P&L'!$A$27,'List of Ledgers '!$G:$G,'P&L'!R6) -> 0 | S27: =-SUMIFS('List of Ledgers '!$Q:$Q,'List of Ledgers '!$F:$F,'P&L'!$A$27,'List of Ledgers '!$G:$G,'P&L'!S6) -> 0 | T27: =-SUMIFS('List of Ledgers '!$Q:$Q,'List of Ledgers '!$F:$F,'P&L'!$A$27,'List of Ledgers '!$G:$G,'P&L'!T6) -> 0 | U27: =-SUMIFS('List of Ledgers '!$Q:$Q,'List of Ledgers '!$F:$F,'P&L'!$A$27,'List of Ledgers '!$G:$G,'P&L'!U6) -> 0 | V27: =SUM(N27:U27) -> 0 | W27: =-SUMIFS('List of Ledgers '!$Q:$Q,'List of Ledgers '!$F:$F,'P&L'!$A$27,'List of Ledgers '!$G:$G,'P&L'!W6) -> 23630.29 | X27: =SUM(V27:W27) -> 23630.29 | Y27: =V27-X27 -> -23630.29
A28: Capital Loss | B28: =SUMIFS('List of Ledgers '!$L:$L,'List of Ledgers '!$F:$F,'P&L'!$A$28,'List of Ledgers '!$G:$G,'P&L'!B6) -> 0 | C28: =SUMIFS('List of Ledgers '!$L:$L,'List of Ledgers '!$F:$F,'P&L'!$A$28,'List of Ledgers '!$G:$G,'P&L'!C6) -> 0 | D28: =SUMIFS('List of Ledgers '!$L:$L,'List of Ledgers '!$F:$F,'P&L'!$A$28,'List of Ledgers '!$G:$G,'P&L'!D6) -> 0 | E28: =SUMIFS('List of Ledgers '!$L:$L,'List of Ledgers '!$F:$F,'P&L'!$A$28,'List of Ledgers '!$G:$G,'P&L'!E6) -> 0 | F28: =SUMIFS('List of Ledgers '!$L:$L,'List of Ledgers '!$F:$F,'P&L'!$A$28,'List of Ledgers '!$G:$G,'P&L'!F6) -> 0 | G28: =SUMIFS('List of Ledgers '!$L:$L,'List of Ledgers '!$F:$F,'P&L'!$A$28,'List of Ledgers '!$G:$G,'P&L'!G6) -> 0 | H28: =SUMIFS('List of Ledgers '!$L:$L,'List of Ledgers '!$F:$F,'P&L'!$A$28,'List of Ledgers '!$G:$G,'P&L'!H6) -> 0 | I28: =SUMIFS('List of Ledgers '!$L:$L,'List of Ledgers '!$F:$F,'P&L'!$A$28,'List of Ledgers '!$G:$G,'P&L'!I6) -> 0 | J28: =SUM(B28:I28) -> 0 | K28: =SUMIFS('List of Ledgers '!$L:$L,'List of Ledgers '!$F:$F,'P&L'!$A$28,'List of Ledgers '!$G:$G,'P&L'!K6) -> 0 | L28: =J28+K28 -> 0 | N28: =-SUMIFS('List of Ledgers '!$Q:$Q,'List of Ledgers '!$F:$F,$A$28,'List of Ledgers '!$G:$G,'P&L'!N6) -> 0 | O28: =-SUMIFS('List of Ledgers '!$Q:$Q,'List of Ledgers '!$F:$F,$A$28,'List of Ledgers '!$G:$G,'P&L'!O6) -> 0 | P28: =-SUMIFS('List of Ledgers '!$Q:$Q,'List of Ledgers '!$F:$F,$A$28,'List of Ledgers '!$G:$G,'P&L'!P6) -> 0 | Q28: =-SUMIFS('List of Ledgers '!$Q:$Q,'List of Ledgers '!$F:$F,$A$28,'List of Ledgers '!$G:$G,'P&L'!Q6) -> 0 | R28: =-SUMIFS('List of Ledgers '!$Q:$Q,'List of Ledgers '!$F:$F,$A$28,'List of Ledgers '!$G:$G,'P&L'!R6) -> 0 | S28: =-SUMIFS('List of Ledgers '!$Q:$Q,'List of Ledgers '!$F:$F,$A$28,'List of Ledgers '!$G:$G,'P&L'!S6) -> 0 | T28: =-SUMIFS('List of Ledgers '!$Q:$Q,'List of Ledgers '!$F:$F,$A$28,'List of Ledgers '!$G:$G,'P&L'!T6) -> 0 | U28: =-SUMIFS('List of Ledgers '!$Q:$Q,'List of Ledgers '!$F:$F,$A$28,'List of Ledgers '!$G:$G,'P&L'!U6) -> 0 | ... W28: =-SUMIFS('List of Ledgers '!$Q:$Q,'List of Ledgers '!$F:$F,$A$28,'List of Ledgers '!$G:$G,'P&L'!W6) -> -711054.97 | X28: =SUM(V28:W28) -> -711054.97 | Y28: =V28-X28 -> 711054.97
Y29: =V29-X29 -> 0
A30: Depreciation & amortization | B30: 0 | C30: 0 | D30: 0 | E30: 0 | F30: 0 | K30: 0 | L30: =SUM(J30:K30) -> 0 | N30: 0 | O30: 0 | P30: 0 | Q30: 0 | R30: 0 | W30: 0 | X30: =SUM(V30:W30) -> 0 | Y30: =V30-X30 -> 0
A31: Net income | B31: =B20+B16 -> 0 | C31: =C20+C16 -> 2.910383e-11 | D31: =D20+D16 -> 16903580 | E31: =E20+E16 -> 0 | F31: =F20+F16 -> 0 | G31: =G20+G16 -> -35050 | H31: =H20+H16 -> 200000 | I31: =I20+I16 -> 3336179.8 | ... L31: =L20+L16 -> 20404709 | N31: =N20+N16 -> -61053.05 | O31: =O20+O16 -> 328384.55 | P31: =P20+P16 -> 20429747 | Q31: =Q20+Q16 -> 0 | R31: =R20+R16 -> 0 | S31: =S20+S16 -> 613357.44 | T31: =T20+T16 -> 200000 | U31: =U20+U16 -> 5640355.4 | ... X31: =X20+X16 -> 26939437 | Y31: =V31-X31 -> 211354.2
A32: Net allocable income | B32: 0 | C32: =G31*C7/J7 -> -13.281222 | D32: {=SUM($G$30:$G$30/4)} -> 0 | E32: 0 | F32: 0 | G32: =-G31 -> 35050 | H32: {=SUM($G$30:$G$30/4)} -> 0 | I32: =G31*I7/J7 -> -35036.719 | J32: =SUM(B32:I32) -> 0 | K32: =-K31 -> 0 | L32: =SUM(J32:K32) -> 0 | N32: =S31*N7/V7 -> 4757.0245 | O32: =S31*O7/V7 -> 2250.543 | P32: =S31*P7/V7 -> 284267.13 | R32: 0 | S32: =-S31 -> -613357.44 | T32: =-T31 -> -200000 | U32: =S31*U7/V7 -> 322082.74 | V32: =SUM(N32:U32) -> -200000 | W32: =-W31 -> 211354.2 | X32: =SUM(V32:W32) -> 11354.2 | Y32: =V32-X32 -> -211354.2
Y33: =V33-X33 -> 0
Y34: =V34-X34 -> 0
A35: 6. Indirect Expense | Y35: =V35-X35 -> 0
A36: Audit Fees | B36: =SUMIFS('List of Ledgers '!$L:$L,'List of Ledgers '!$F:$F,'P&L'!$A$36,'List of Ledgers '!$G:$G,'P&L'!B$6) -> 0 | C36: =SUMIFS('List of Ledgers '!$L:$L,'List of Ledgers '!$F:$F,'P&L'!$A$36,'List of Ledgers '!$G:$G,'P&L'!C6) -> 0 | D36: =SUMIFS('List of Ledgers '!$L:$L,'List of Ledgers '!$F:$F,'P&L'!$A$36,'List of Ledgers '!$G:$G,'P&L'!D6) -> 0 | E36: =SUMIFS('List of Ledgers '!$L:$L,'List of Ledgers '!$F:$F,'P&L'!$A$36,'List of Ledgers '!$G:$G,'P&L'!E6) -> 0 | F36: =SUMIFS('List of Ledgers '!$L:$L,'List of Ledgers '!$F:$F,'P&L'!$A$36,'List of Ledgers '!$G:$G,'P&L'!F6) -> 0 | G36: =SUMIFS('List of Ledgers '!$L:$L,'List of Ledgers '!$F:$F,'P&L'!$A$36,'List of Ledgers '!$G:$G,'P&L'!G6) -> 0 | H36: =SUMIFS('List of Ledgers '!$L:$L,'List of Ledgers '!$F:$F,'P&L'!$A$36,'List of Ledgers '!$G:$G,'P&L'!H6) -> 0 | I36: =SUMIFS('List of Ledgers '!$L:$L,'List of Ledgers '!$F:$F,'P&L'!$A$36,'List of Ledgers '!$G:$G,'P&L'!I6) -> 0 | J36: =SUM(B36:I36) -> 0 | K36: =SUMIFS('List of Ledgers '!$L:$L,'List of Ledgers '!$F:$F,'P&L'!$A36,'List of Ledgers '!$G:$G,'P&L'!$K$6) -> 0 | L36: =J36+K36 -> 0 | N36: =SUMIFS('List of Ledgers '!$Q:$Q,'List of Ledgers '!$F:$F,'P&L'!$A36,'List of Ledgers '!$G:$G,'P&L'!N$6) -> 0 | O36: =SUMIFS('List of Ledgers '!$Q:$Q,'List of Ledgers '!$F:$F,'P&L'!$A36,'List of Ledgers '!$G:$G,'P&L'!O$6) -> 0 | P36: =SUMIFS('List of Ledgers '!$Q:$Q,'List of Ledgers '!$F:$F,'P&L'!$A36,'List of Ledgers '!$G:$G,'P&L'!P$6) -> 0 | Q36: =SUMIFS('List of Ledgers '!$Q:$Q,'List of Ledgers '!$F:$F,'P&L'!$A36,'List of Ledgers '!$G:$G,'P&L'!Q$6) -> 0 | R36: =SUMIFS('List of Ledgers '!$Q:$Q,'List of Ledgers '!$F:$F,'P&L'!$A36,'List of Ledgers '!$G:$G,'P&L'!R$6) -> 0 | S36: =SUMIFS('List of Ledgers '!$Q:$Q,'List of Ledgers '!$F:$F,'P&L'!$A36,'List of Ledgers '!$G:$G,'P&L'!S$6) -> 220000 | T36: =SUMIFS('List of Ledgers '!$Q:$Q,'List of Ledgers '!$F:$F,'P&L'!$A36,'List of Ledgers '!$G:$G,'P&L'!T$6) -> 0 | U36: =SUMIFS('List of Ledgers '!$Q:$Q,'List of Ledgers '!$F:$F,'P&L'!$A36,'List of Ledgers '!$G:$G,'P&L'!U$6) -> 0 | V36: =SUM(N36:U36) -> 220000 | W36: =SUMIFS('List of Ledgers '!$Q:$Q,'List of Ledgers '!$F:$F,'P&L'!$A36,'List of Ledgers '!$G:$G,'P&L'!W$6) -> 0 | X36: =V36+W36 -> 220000 | Y36: =V36-X36 -> 0
A37: Accomodation expenses | B37: =SUMIFS('List of Ledgers '!$L:$L,'List of Ledgers '!$F:$F,'P&L'!$A37,'List of Ledgers '!$G:$G,'P&L'!B$6) -> 0 | C37: =SUMIFS('List of Ledgers '!$L:$L,'List of Ledgers '!$F:$F,'P&L'!$A37,'List of Ledgers '!$G:$G,'P&L'!C$6) -> 0 | D37: =SUMIFS('List of Ledgers '!$L:$L,'List of Ledgers '!$F:$F,'P&L'!$A37,'List of Ledgers '!$G:$G,'P&L'!D$6) -> 81813.94 | E37: =SUMIFS('List of Ledgers '!$L:$L,'List of Ledgers '!$F:$F,'P&L'!$A37,'List of Ledgers '!$G:$G,'P&L'!E$6) -> 0 | F37: =SUMIFS('List of Ledgers '!$L:$L,'List of Ledgers '!$F:$F,'P&L'!$A37,'List of Ledgers '!$G:$G,'P&L'!F$6) -> 0 | G37: =SUMIFS('List of Ledgers '!$L:$L,'List of Ledgers '!$F:$F,'P&L'!$A37,'List of Ledgers '!$G:$G,'P&L'!G$6) -> 0 | H37: =SUMIFS('List of Ledgers '!$L:$L,'List of Ledgers '!$F:$F,'P&L'!$A37,'List of Ledgers '!$G:$G,'P&L'!H$6) -> 0 | I37: =SUMIFS('List of Ledgers '!$L:$L,'List of Ledgers '!$F:$F,'P&L'!$A37,'List of Ledgers '!$G:$G,'P&L'!I$6) -> 0 | J37: =SUM(B37:I37) -> 81813.94 | K37: =SUMIFS('List of Ledgers '!$L:$L,'List of Ledgers '!$F:$F,'P&L'!$A37,'List of Ledgers '!$G:$G,'P&L'!$K$6) -> 0 | L37: =J37+K37 -> 81813.94 | N37: =SUMIFS('List of Ledgers '!$Q:$Q,'List of Ledgers '!$F:$F,'P&L'!$A37,'List of Ledgers '!$G:$G,'P&L'!N$6) -> 0 | O37: =SUMIFS('List of Ledgers '!$Q:$Q,'List of Ledgers '!$F:$F,'P&L'!$A37,'List of Ledgers '!$G:$G,'P&L'!O$6) -> 0 | P37: =SUMIFS('List of Ledgers '!$Q:$Q,'List of Ledgers '!$F:$F,'P&L'!$A37,'List of Ledgers '!$G:$G,'P&L'!P$6) -> 299599.94 | Q37: =SUMIFS('List of Ledgers '!$Q:$Q,'List of Ledgers '!$F:$F,'P&L'!$A37,'List of Ledgers '!$G:$G,'P&L'!Q$6) -> 0 | R37: =SUMIFS('List of Ledgers '!$Q:$Q,'List of Ledgers '!$F:$F,'P&L'!$A37,'List of Ledgers '!$G:$G,'P&L'!R$6) -> 0 | S37: =SUMIFS('List of Ledgers '!$Q:$Q,'List of Ledgers '!$F:$F,'P&L'!$A37,'List of Ledgers '!$G:$G,'P&L'!S$6) -> 0 | V37: =SUM(N37:U37) -> 299599.94 | W37: =SUMIFS('List of Ledgers '!$Q:$Q,'List of Ledgers '!$F:$F,'P&L'!$A37,'List of Ledgers '!$G:$G,'P&L'!W$6) -> 0 | X37: =V37+W37 -> 299599.94 | Y37: =V37-X37 -> 0
A38: Advertisement | B38: =SUMIFS('List of Ledgers '!$L:$L,'List of Ledgers '!$F:$F,'P&L'!$A38,'List of Ledgers '!$G:$G,'P&L'!B$6) -> 0 | C38: =SUMIFS('List of Ledgers '!$L:$L,'List of Ledgers '!$F:$F,'P&L'!$A38,'List of Ledgers '!$G:$G,'P&L'!C$6) -> 0 | D38: =SUMIFS('List of Ledgers '!$L:$L,'List of Ledgers '!$F:$F,'P&L'!$A38,'List of Ledgers '!$G:$G,'P&L'!D$6) -> 0 | E38: =SUMIFS('List of Ledgers '!$L:$L,'List of Ledgers '!$F:$F,'P&L'!$A38,'List of Ledgers '!$G:$G,'P&L'!E$6) -> 0 | F38: =SUMIFS('List of Ledgers '!$L:$L,'List of Ledgers '!$F:$F,'P&L'!$A38,'List of Ledgers '!$G:$G,'P&L'!F$6) -> 0 | G38: =SUMIFS('List of Ledgers '!$L:$L,'List of Ledgers '!$F:$F,'P&L'!$A38,'List of Ledgers '!$G:$G,'P&L'!G$6) -> 0 | H38: =SUMIFS('List of Ledgers '!$L:$L,'List of Ledgers '!$F:$F,'P&L'!$A38,'List of Ledgers '!$G:$G,'P&L'!H$6) -> 0 | I38: =SUMIFS('List of Ledgers '!$L:$L,'List of Ledgers '!$F:$F,'P&L'!$A38,'List of Ledgers '!$G:$G,'P&L'!I$6) -> 0 | J38: =SUM(B38:I38) -> 0 | K38: =SUMIFS('List of Ledgers '!$L:$L,'List of Ledgers '!$F:$F,'P&L'!$A38,'List of Ledgers '!$G:$G,'P&L'!$K$6) -> 0 | L38: =J38+K38 -> 0 | N38: =SUMIFS('List of Ledgers '!$Q:$Q,'List of Ledgers '!$F:$F,'P&L'!$A38,'List of Ledgers '!$G:$G,'P&L'!N$6) -> 0 | O38: =SUMIFS('List of Ledgers '!$Q:$Q,'List of Ledgers '!$F:$F,'P&L'!$A38,'List of Ledgers '!$G:$G,'P&L'!O$6) -> 0 | P38: =SUMIFS('List of Ledgers '!$Q:$Q,'List of Ledgers '!$F:$F,'P&L'!$A38,'List of Ledgers '!$G:$G,'P&L'!P$6) -> 0 | Q38: =SUMIFS('List of Ledgers '!$Q:$Q,'List of Ledgers '!$F:$F,'P&L'!$A38,'List of Ledgers '!$G:$G,'P&L'!Q$6) -> 0 | R38: =SUMIFS('List of Ledgers '!$Q:$Q,'List of Ledgers '!$F:$F,'P&L'!$A38,'List of Ledgers '!$G:$G,'P&L'!R$6) -> 0 | S38: =SUMIFS('List of Ledgers '!$Q:$Q,'List of Ledgers '!$F:$F,'P&L'!$A38,'List of Ledgers '!$G:$G,'P&L'!S$6) -> 0 | T38: =SUMIFS('List of Ledgers '!$Q:$Q,'List of Ledgers '!$F:$F,'P&L'!$A38,'List of Ledgers '!$G:$G,'P&L'!T$6) -> 0 | U38: =SUMIFS('List of Ledgers '!$Q:$Q,'List of Ledgers '!$F:$F,'P&L'!$A38,'List of Ledgers '!$G:$G,'P&L'!U$6) -> 0 | V38: =SUM(N38:U38) -> 0 | W38: =SUMIFS('List of Ledgers '!$Q:$Q,'List of Ledgers '!$F:$F,'P&L'!$A38,'List of Ledgers '!$G:$G,'P&L'!W$6) -> 0 | X38: =V38+W38 -> 0 | Y38: =V38-X38 -> 0
A39: Bad debt | B39: =SUMIFS('List of Ledgers '!$L:$L,'List of Ledgers '!$F:$F,'P&L'!$A39,'List of Ledgers '!$G:$G,'P&L'!B$6) -> 0 | C39: =SUMIFS('List of Ledgers '!$L:$L,'List of Ledgers '!$F:$F,'P&L'!$A39,'List of Ledgers '!$G:$G,'P&L'!C$6) -> 0 | D39: =SUMIFS('List of Ledgers '!$L:$L,'List of Ledgers '!$F:$F,'P&L'!$A39,'List of Ledgers '!$G:$G,'P&L'!D$6) -> 0 | E39: =SUMIFS('List of Ledgers '!$L:$L,'List of Ledgers '!$F:$F,'P&L'!$A39,'List of Ledgers '!$G:$G,'P&L'!E$6) -> 0 | F39: =SUMIFS('List of Ledgers '!$L:$L,'List of Ledgers '!$F:$F,'P&L'!$A39,'List of Ledgers '!$G:$G,'P&L'!F$6) -> 0 | G39: =SUMIFS('List of Ledgers '!$L:$L,'List of Ledgers '!$F:$F,'P&L'!$A39,'List of Ledgers '!$G:$G,'P&L'!G$6) -> 0 | H39: =SUMIFS('List of Ledgers '!$L:$L,'List of Ledgers '!$F:$F,'P&L'!$A39,'List of Ledgers '!$G:$G,'P&L'!H$6) -> 0 | I39: =SUMIFS('List of Ledgers '!$L:$L,'List of Ledgers '!$F:$F,'P&L'!$A39,'List of Ledgers '!$G:$G,'P&L'!I$6) -> 0 | J39: =SUM(B39:I39) -> 0 | K39: =SUMIFS('List of Ledgers '!$L:$L,'List of Ledgers '!$F:$F,'P&L'!$A39,'List of Ledgers '!$G:$G,'P&L'!$K$6) -> 0 | L39: =J39+K39 -> 0 | N39: =SUMIFS('List of Ledgers '!$Q:$Q,'List of Ledgers '!$F:$F,'P&L'!$A39,'List of Ledgers '!$G:$G,'P&L'!N$6) -> 0 | O39: =SUMIFS('List of Ledgers '!$Q:$Q,'List of Ledgers '!$F:$F,'P&L'!$A39,'List of Ledgers '!$G:$G,'P&L'!O$6) -> 0 | P39: =SUMIFS('List of Ledgers '!$Q:$Q,'List of Ledgers '!$F:$F,'P&L'!$A39,'List of Ledgers '!$G:$G,'P&L'!P$6) -> 0 | Q39: =SUMIFS('List of Ledgers '!$Q:$Q,'List of Ledgers '!$F:$F,'P&L'!$A39,'List of Ledgers '!$G:$G,'P&L'!Q$6) -> 0 | R39: =SUMIFS('List of Ledgers '!$Q:$Q,'List of Ledgers '!$F:$F,'P&L'!$A39,'List of Ledgers '!$G:$G,'P&L'!R$6) -> 0 | S39: =SUMIFS('List of Ledgers '!$Q:$Q,'List of Ledgers '!$F:$F,'P&L'!$A39,'List of Ledgers '!$G:$G,'P&L'!S$6) -> 0 | T39: =SUMIFS('List of Ledgers '!$Q:$Q,'List of Ledgers '!$F:$F,'P&L'!$A39,'List of Ledgers '!$G:$G,'P&L'!T$6) -> 0 | U39: =SUMIFS('List of Ledgers '!$Q:$Q,'List of Ledgers '!$F:$F,'P&L'!$A39,'List of Ledgers '!$G:$G,'P&L'!U$6) -> 0 | V39: =SUM(N39:U39) -> 0 | W39: =SUMIFS('List of Ledgers '!$Q:$Q,'List of Ledgers '!$F:$F,'P&L'!$A39,'List of Ledgers '!$G:$G,'P&L'!W$6) -> 0 | X39: =V39+W39 -> 0 | Y39: =V39-X39 -> 0
A40: Marketing Expense | B40: ='Marketing Expenses'!B12 -> 0 | C40: ='Marketing Expenses'!C12 -> 0 | D40: ='Marketing Expenses'!D12 -> 30000 | E40: ='Marketing Expenses'!E12 -> 0 | F40: ='Marketing Expenses'!F12 -> 0 | G40: ='Marketing Expenses'!G12 -> 0 | H40: ='Marketing Expenses'!H12 -> 4000 | I40: ='Marketing Expenses'!I12 -> 0 | J40: =SUM(B40:I40) -> 34000 | K40: =SUMIFS('List of Ledgers '!$L:$L,'List of Ledgers '!$F:$F,'P&L'!$A40,'List of Ledgers '!$G:$G,'P&L'!$K$6) -> 0 | L40: =J40+K40 -> 34000 | N40: ='Marketing Expenses'!N12 -> 0 | O40: ='Marketing Expenses'!O12 -> 0 | P40: ='Marketing Expenses'!P12 -> 194200.82 | Q40: ='Marketing Expenses'!Q12 -> 0 | R40: ='Marketing Expenses'!R12 -> 0 | S40: ='Marketing Expenses'!S12 -> 11572 | T40: ='Marketing Expenses'!T12 -> 691055 | U40: ='Marketing Expenses'!U12 -> 552704 | V40: =SUM(N40:U40) -> 1449531.8 | W40: ='Marketing Expenses'!W12 -> 0 | X40: =V40+W40 -> 1449531.8 | Y40: =V40-X40 -> 0
A41: Bank charges | B41: =SUMIFS('List of Ledgers '!$L:$L,'List of Ledgers '!$F:$F,'P&L'!$A41,'List of Ledgers '!$G:$G,'P&L'!B$6) -> 0 | C41: =SUMIFS('List of Ledgers '!$L:$L,'List of Ledgers '!$F:$F,'P&L'!$A41,'List of Ledgers '!$G:$G,'P&L'!C$6) -> 0 | D41: =SUMIFS('List of Ledgers '!$L:$L,'List of Ledgers '!$F:$F,'P&L'!$A41,'List of Ledgers '!$G:$G,'P&L'!D$6) -> 600 | E41: =SUMIFS('List of Ledgers '!$L:$L,'List of Ledgers '!$F:$F,'P&L'!$A41,'List of Ledgers '!$G:$G,'P&L'!E$6) -> 0 | F41: =SUMIFS('List of Ledgers '!$L:$L,'List of Ledgers '!$F:$F,'P&L'!$A41,'List of Ledgers '!$G:$G,'P&L'!F$6) -> 0 | G41: =SUMIFS('List of Ledgers '!$L:$L,'List of Ledgers '!$F:$F,'P&L'!$A41,'List of Ledgers '!$G:$G,'P&L'!G$6) -> 624.32 | H41: =SUMIFS('List of Ledgers '!$L:$L,'List of Ledgers '!$F:$F,'P&L'!$A41,'List of Ledgers '!$G:$G,'P&L'!H$6) -> 0 | I41: =SUMIFS('List of Ledgers '!$L:$L,'List of Ledgers '!$F:$F,'P&L'!$A41,'List of Ledgers '!$G:$G,'P&L'!I$6) -> 1817.7 | J41: =SUM(B41:I41) -> 3042.02 | K41: =SUMIFS('List of Ledgers '!$L:$L,'List of Ledgers '!$F:$F,'P&L'!$A41,'List of Ledgers '!$G:$G,'P&L'!$K$6) -> 0 | L41: =J41+K41 -> 3042.02 | N41: =SUMIFS('List of Ledgers '!$Q:$Q,'List of Ledgers '!$F:$F,'P&L'!$A41,'List of Ledgers '!$G:$G,'P&L'!N$6) -> 0 | O41: =SUMIFS('List of Ledgers '!$Q:$Q,'List of Ledgers '!$F:$F,'P&L'!$A41,'List of Ledgers '!$G:$G,'P&L'!O$6) -> 0 | P41: =SUMIFS('List of Ledgers '!$Q:$Q,'List of Ledgers '!$F:$F,'P&L'!$A41,'List of Ledgers '!$G:$G,'P&L'!P$6) -> 2650 | Q41: =SUMIFS('List of Ledgers '!$Q:$Q,'List of Ledgers '!$F:$F,'P&L'!$A41,'List of Ledgers '!$G:$G,'P&L'!Q$6) -> 0 | R41: =SUMIFS('List of Ledgers '!$Q:$Q,'List of Ledgers '!$F:$F,'P&L'!$A41,'List of Ledgers '!$G:$G,'P&L'!R$6) -> 0 | S41: =SUMIFS('List of Ledgers '!$Q:$Q,'List of Ledgers '!$F:$F,'P&L'!$A41,'List of Ledgers '!$G:$G,'P&L'!S$6) -> 7258.68 | T41: =SUMIFS('List of Ledgers '!$Q:$Q,'List of Ledgers '!$F:$F,'P&L'!$A41,'List of Ledgers '!$G:$G,'P&L'!T$6) -> 0 | U41: =SUMIFS('List of Ledgers '!$Q:$Q,'List of Ledgers '!$F:$F,'P&L'!$A41,'List of Ledgers '!$G:$G,'P&L'!U$6) -> 4385.4 | V41: =SUM(N41:U41) -> 14294.08 | W41: =SUMIFS('List of Ledgers '!$Q:$Q,'List of Ledgers '!$F:$F,'P&L'!$A41,'List of Ledgers '!$G:$G,'P&L'!W$6) -> 0 | X41: =V41+W41 -> 14294.08 | Y41: =V41-X41 -> 0
...

Sheet Marketing Expenses
L1: ='P&L'!L5 -> Mar'26 | N1: ='P&L'!N5 -> (April to Mar) | X1: YTD'26
A2: Expenses Type | B2: Bluestreak | C2: Clarus | D2: IT | E2: Factory | F2: Office | G2: Common | H2: Spices - A to Z | I2: Spices - Vashi | J2: Total (without share trading) | K2: Share Trading | L2: Total (including share trading) | N2: Bluestreak | O2: Clarus | P2: IT | Q2: Factory | R2: Office | S2: Common | T2: Spices - A to Z | U2: Spices - Vashi | V2: Total (without share trading) | W2: Share Trading | X2: Total (including share trading)
A3: Creative agency charges | B3: =SUMIFS('List of Ledgers '!$L:$L,'List of Ledgers '!$F:$F,'Marketing Expenses'!$A3,'List of Ledgers '!$G:$G,'Marketing Expenses'!B$2) -> 0 | C3: =SUMIFS('List of Ledgers '!$L:$L,'List of Ledgers '!$F:$F,'Marketing Expenses'!$A3,'List of Ledgers '!$G:$G,'Marketing Expenses'!C$2) -> 0 | D3: =SUMIFS('List of Ledgers '!$L:$L,'List of Ledgers '!$F:$F,'Marketing Expenses'!$A3,'List of Ledgers '!$G:$G,'Marketing Expenses'!D$2) -> 0 | E3: =SUMIFS('List of Ledgers '!$L:$L,'List of Ledgers '!$F:$F,'Marketing Expenses'!$A3,'List of Ledgers '!$G:$G,'Marketing Expenses'!E$2) -> 0 | F3: =SUMIFS('List of Ledgers '!$L:$L,'List of Ledgers '!$F:$F,'Marketing Expenses'!$A3,'List of Ledgers '!$G:$G,'Marketing Expenses'!F$2) -> 0 | G3: =SUMIFS('List of Ledgers '!$L:$L,'List of Ledgers '!$F:$F,'Marketing Expenses'!$A3,'List of Ledgers '!$G:$G,'Marketing Expenses'!G$2) -> 0 | H3: =SUMIFS('List of Ledgers '!$L:$L,'List of Ledgers '!$F:$F,'Marketing Expenses'!$A3,'List of Ledgers '!$G:$G,'Marketing Expenses'!H$2) -> 0 | I3: =SUMIFS('List of Ledgers '!$L:$L,'List of Ledgers '!$F:$F,'Marketing Expenses'!$A3,'List of Ledgers '!$G:$G,'Marketing Expenses'!I$2) -> 0 | J3: =SUM(B3:I3) -> 0 | K3: =SUMIFS('List of Ledgers '!$L:$L,'List of Ledgers '!$F:$F,'Marketing Expenses'!$A3,'List of Ledgers '!$G:$G,'Marketing Expenses'!K$2) -> 0 | L3: =J3+K3 -> 0 | N3: =SUMIFS('List of Ledgers '!$Q:$Q,'List of Ledgers '!$F:$F,'Marketing Expenses'!$A3,'List of Ledgers '!$G:$G,'Marketing Expenses'!N$2) -> 0 | O3: =SUMIFS('List of Ledgers '!$Q:$Q,'List of Ledgers '!$F:$F,'Marketing Expenses'!$A3,'List of Ledgers '!$G:$G,'Marketing Expenses'!O$2) -> 0 | P3: =SUMIFS('List of Ledgers '!$Q:$Q,'List of Ledgers '!$F:$F,'Marketing Expenses'!$A3,'List of Ledgers '!$G:$G,'Marketing Expenses'!P$2) -> 0 | Q3: =SUMIFS('List of Ledgers '!$Q:$Q,'List of Ledgers '!$F:$F,'Marketing Expenses'!$A3,'List of Ledgers '!$G:$G,'Marketing Expenses'!Q$2) -> 0 | R3: =SUMIFS('List of Ledgers '!$Q:$Q,'List of Ledgers '!$F:$F,'Marketing Expenses'!$A3,'List of Ledgers '!$G:$G,'Marketing Expenses'!R$2) -> 0 | S3: =SUMIFS('List of Ledgers '!$Q:$Q,'List of Ledgers '!$F:$F,'Marketing Expenses'!$A3,'List of Ledgers '!$G:$G,'Marketing Expenses'!S$2) -> 0 | T3: =SUMIFS('List of Ledgers '!$Q:$Q,'List of Ledgers '!$F:$F,'Marketing Expenses'!$A3,'List of Ledgers '!$G:$G,'Marketing Expenses'!T$2) -> 418005 | U3: =SUMIFS('List of Ledgers '!$Q:$Q,'List of Ledgers '!$F:$F,'Marketing Expenses'!$A3,'List of Ledgers '!$G:$G,'Marketing Expenses'!U$2) -> 0 | V3: =SUM(N3:U3) -> 418005 | W3: =SUMIFS('List of Ledgers '!$Q:$Q,'List of Ledgers '!$F:$F,'Marketing Expenses'!$A3,'List of Ledgers '!$G:$G,'Marketing Expenses'!W$2) -> 0 | X3: =W3+V3 -> 418005
A4: Website charges | B4: =SUMIFS('List of Ledgers '!$L:$L,'List of Ledgers '!$F:$F,'Marketing Expenses'!$A4,'List of Ledgers '!$G:$G,'Marketing Expenses'!B$2) -> 0 | C4: =SUMIFS('List of Ledgers '!$L:$L,'List of Ledgers '!$F:$F,'Marketing Expenses'!$A4,'List of Ledgers '!$G:$G,'Marketing Expenses'!C$2) -> 0 | D4: =SUMIFS('List of Ledgers '!$L:$L,'List of Ledgers '!$F:$F,'Marketing Expenses'!$A4,'List of Ledgers '!$G:$G,'Marketing Expenses'!D$2) -> 0 | E4: =SUMIFS('List of Ledgers '!$L:$L,'List of Ledgers '!$F:$F,'Marketing Expenses'!$A4,'List of Ledgers '!$G:$G,'Marketing Expenses'!E$2) -> 0 | F4: =SUMIFS('List of Ledgers '!$L:$L,'List of Ledgers '!$F:$F,'Marketing Expenses'!$A4,'List of Ledgers '!$G:$G,'Marketing Expenses'!F$2) -> 0 | G4: =SUMIFS('List of Ledgers '!$L:$L,'List of Ledgers '!$F:$F,'Marketing Expenses'!$A4,'List of Ledgers '!$G:$G,'Marketing Expenses'!G$2) -> 0 | H4: =SUMIFS('List of Ledgers '!$L:$L,'List of Ledgers '!$F:$F,'Marketing Expenses'!$A4,'List of Ledgers '!$G:$G,'Marketing Expenses'!H$2) -> 0 | I4: =SUMIFS('List of Ledgers '!$L:$L,'List of Ledgers '!$F:$F,'Marketing Expenses'!$A4,'List of Ledgers '!$G:$G,'Marketing Expenses'!I$2) -> 0 | J4: =SUM(B4:I4) -> 0 | K4: =SUMIFS('List of Ledgers '!$L:$L,'List of Ledgers '!$F:$F,'Marketing Expenses'!$A4,'List of Ledgers '!$G:$G,'Marketing Expenses'!K$2) -> 0 | L4: =J4+K4 -> 0 | N4: =SUMIFS('List of Ledgers '!$Q:$Q,'List of Ledgers '!$F:$F,'Marketing Expenses'!$A4,'List of Ledgers '!$G:$G,'Marketing Expenses'!N$2) -> 0 | O4: =SUMIFS('List of Ledgers '!$Q:$Q,'List of Ledgers '!$F:$F,'Marketing Expenses'!$A4,'List of Ledgers '!$G:$G,'Marketing Expenses'!O$2) -> 0 | P4: =SUMIFS('List of Ledgers '!$Q:$Q,'List of Ledgers '!$F:$F,'Marketing Expenses'!$A4,'List of Ledgers '!$G:$G,'Marketing Expenses'!P$2) -> 0 | Q4: =SUMIFS('List of Ledgers '!$Q:$Q,'List of Ledgers '!$F:$F,'Marketing Expenses'!$A4,'List of Ledgers '!$G:$G,'Marketing Expenses'!Q$2) -> 0 | R4: =SUMIFS('List of Ledgers '!$Q:$Q,'List of Ledgers '!$F:$F,'Marketing Expenses'!$A4,'List of Ledgers '!$G:$G,'Marketing Expenses'!R$2) -> 0 | S4: =SUMIFS('List of Ledgers '!$Q:$Q,'List of Ledgers '!$F:$F,'Marketing Expenses'!$A4,'List of Ledgers '!$G:$G,'Marketing Expenses'!S$2) -> 10711 | T4: =SUMIFS('List of Ledgers '!$Q:$Q,'List of Ledgers '!$F:$F,'Marketing Expenses'!$A4,'List of Ledgers '!$G:$G,'Marketing Expenses'!T$2) -> 0 | U4: =SUMIFS('List of Ledgers '!$Q:$Q,'List of Ledgers '!$F:$F,'Marketing Expenses'!$A4,'List of Ledgers '!$G:$G,'Marketing Expenses'!U$2) -> 0 | V4: =SUM(N4:U4) -> 10711 | W4: =SUMIFS('List of Ledgers '!$Q:$Q,'List of Ledgers '!$F:$F,'Marketing Expenses'!$A4,'List of Ledgers '!$G:$G,'Marketing Expenses'!W$2) -> 0 | X4: =W4+V4 -> 10711
A5: SEO charges | B5: =SUMIFS('List of Ledgers '!$L:$L,'List of Ledgers '!$F:$F,'Marketing Expenses'!$A5,'List of Ledgers '!$G:$G,'Marketing Expenses'!B$2) -> 0 | C5: =SUMIFS('List of Ledgers '!$L:$L,'List of Ledgers '!$F:$F,'Marketing Expenses'!$A5,'List of Ledgers '!$G:$G,'Marketing Expenses'!C$2) -> 0 | D5: =SUMIFS('List of Ledgers '!$L:$L,'List of Ledgers '!$F:$F,'Marketing Expenses'!$A5,'List of Ledgers '!$G:$G,'Marketing Expenses'!D$2) -> 0 | E5: =SUMIFS('List of Ledgers '!$L:$L,'List of Ledgers '!$F:$F,'Marketing Expenses'!$A5,'List of Ledgers '!$G:$G,'Marketing Expenses'!E$2) -> 0 | F5: =SUMIFS('List of Ledgers '!$L:$L,'List of Ledgers '!$F:$F,'Marketing Expenses'!$A5,'List of Ledgers '!$G:$G,'Marketing Expenses'!F$2) -> 0 | G5: =SUMIFS('List of Ledgers '!$L:$L,'List of Ledgers '!$F:$F,'Marketing Expenses'!$A5,'List of Ledgers '!$G:$G,'Marketing Expenses'!G$2) -> 0 | H5: =SUMIFS('List of Ledgers '!$L:$L,'List of Ledgers '!$F:$F,'Marketing Expenses'!$A5,'List of Ledgers '!$G:$G,'Marketing Expenses'!H$2) -> 0 | I5: =SUMIFS('List of Ledgers '!$L:$L,'List of Ledgers '!$F:$F,'Marketing Expenses'!$A5,'List of Ledgers '!$G:$G,'Marketing Expenses'!I$2) -> 0 | J5: =SUM(B5:I5) -> 0 | K5: =SUMIFS('List of Ledgers '!$L:$L,'List of Ledgers '!$F:$F,'Marketing Expenses'!$A5,'List of Ledgers '!$G:$G,'Marketing Expenses'!K$2) -> 0 | L5: =J5+K5 -> 0 | N5: =SUMIFS('List of Ledgers '!$Q:$Q,'List of Ledgers '!$F:$F,'Marketing Expenses'!$A5,'List of Ledgers '!$G:$G,'Marketing Expenses'!N$2) -> 0 | O5: =SUMIFS('List of Ledgers '!$Q:$Q,'List of Ledgers '!$F:$F,'Marketing Expenses'!$A5,'List of Ledgers '!$G:$G,'Marketing Expenses'!O$2) -> 0 | P5: =SUMIFS('List of Ledgers '!$Q:$Q,'List of Ledgers '!$F:$F,'Marketing Expenses'!$A5,'List of Ledgers '!$G:$G,'Marketing Expenses'!P$2) -> 0 | Q5: =SUMIFS('List of Ledgers '!$Q:$Q,'List of Ledgers '!$F:$F,'Marketing Expenses'!$A5,'List of Ledgers '!$G:$G,'Marketing Expenses'!Q$2) -> 0 | R5: =SUMIFS('List of Ledgers '!$Q:$Q,'List of Ledgers '!$F:$F,'Marketing Expenses'!$A5,'List of Ledgers '!$G:$G,'Marketing Expenses'!R$2) -> 0 | S5: =SUMIFS('List of Ledgers '!$Q:$Q,'List of Ledgers '!$F:$F,'Marketing Expenses'!$A5,'List of Ledgers '!$G:$G,'Marketing Expenses'!S$2) -> 0 | T5: =SUMIFS('List of Ledgers '!$Q:$Q,'List of Ledgers '!$F:$F,'Marketing Expenses'!$A5,'List of Ledgers '!$G:$G,'Marketing Expenses'!T$2) -> 0 | U5: =SUMIFS('List of Ledgers '!$Q:$Q,'List of Ledgers '!$F:$F,'Marketing Expenses'!$A5,'List of Ledgers '!$G:$G,'Marketing Expenses'!U$2) -> 0 | V5: =SUM(N5:U5) -> 0 | W5: =SUMIFS('List of Ledgers '!$Q:$Q,'List of Ledgers '!$F:$F,'Marketing Expenses'!$A5,'List of Ledgers '!$G:$G,'Marketing Expenses'!W$2) -> 0 | X5: =W5+V5 -> 0
